[2023-09-04 20:15:04,788] ERROR log_exception() L1449 Exception on /marca [POST] - call_trace=C:\mvp\puc-rio-mvp-sprint-3-component-C-2\vm\Lib\site-packages\flask\app.py L1449
Traceback (most recent call last):
  File "C:\mvp\puc-rio-mvp-sprint-3-component-C-2\vm\Lib\site-packages\flask\app.py", line 2073, in wsgi_app
    response = self.full_dispatch_request()
               ^^^^^^^^^^^^^^^^^^^^^^^^^^^^
  File "C:\mvp\puc-rio-mvp-sprint-3-component-C-2\vm\Lib\site-packages\flask\app.py", line 1519, in full_dispatch_request
    rv = self.handle_user_exception(e)
         ^^^^^^^^^^^^^^^^^^^^^^^^^^^^^
  File "C:\mvp\puc-rio-mvp-sprint-3-component-C-2\vm\Lib\site-packages\flask_cors\extension.py", line 165, in wrapped_function
    return cors_after_request(app.make_response(f(*args, **kwargs)))
                                                ^^^^^^^^^^^^^^^^^^
  File "C:\mvp\puc-rio-mvp-sprint-3-component-C-2\vm\Lib\site-packages\flask\app.py", line 1517, in full_dispatch_request
    rv = self.dispatch_request()
         ^^^^^^^^^^^^^^^^^^^^^^^
  File "C:\mvp\puc-rio-mvp-sprint-3-component-C-2\vm\Lib\site-packages\flask\app.py", line 1503, in dispatch_request
    return self.ensure_sync(self.view_functions[rule.endpoint])(**req.view_args)
           ^^^^^^^^^^^^^^^^^^^^^^^^^^^^^^^^^^^^^^^^^^^^^^^^^^^^^^^^^^^^^^^^^^^^^
  File "C:\mvp\puc-rio-mvp-sprint-3-component-C-2\vm\Lib\site-packages\flask_openapi3\scaffold.py", line 191, in wrapper
    resp = _do_wrapper(
           ^^^^^^^^^^^^
  File "C:\mvp\puc-rio-mvp-sprint-3-component-C-2\vm\Lib\site-packages\flask_openapi3\do_wrapper.py", line 135, in _do_wrapper
    response = func(**request_kwargs)
               ^^^^^^^^^^^^^^^^^^^^^^
  File "C:\mvp\puc-rio-mvp-sprint-3-component-C-2\app.py", line 53, in add_marca
    marca = Marca(
      ^^^^^^^^^^^^
TypeError: __init__() got an unexpected keyword argument 'nom_marca'
[2023-09-04 20:15:04,796] INFO _log() L224  127.0.0.1 - - [04/Sep/2023 20:15:04] "[35m[1mPOST /marca HTTP/1.1[0m" 500 - - call_trace=C:\mvp\puc-rio-mvp-sprint-3-component-C-2\vm\Lib\site-packages\werkzeug\_internal.py L224 
[2023-09-04 20:19:47,199] INFO _log() L224   * Running on all addresses (0.0.0.0)
   WARNING: This is a development server. Do not use it in a production deployment.
 * Running on http://127.0.0.1:5000
 * Running on http://192.168.15.138:5000 (Press CTRL+C to quit) - call_trace=C:\mvp\puc-rio-mvp-sprint-3-component-C-2\vm\Lib\site-packages\werkzeug\_internal.py L224 
[2023-09-04 20:19:52,390] INFO _log() L224  127.0.0.1 - - [04/Sep/2023 20:19:52] "GET /openapi/swagger HTTP/1.1" 200 - - call_trace=C:\mvp\puc-rio-mvp-sprint-3-component-C-2\vm\Lib\site-packages\werkzeug\_internal.py L224 
[2023-09-04 20:19:52,490] INFO _log() L224  127.0.0.1 - - [04/Sep/2023 20:19:52] "[36mGET /openapi/static/css/swagger-ui.css HTTP/1.1[0m" 304 - - call_trace=C:\mvp\puc-rio-mvp-sprint-3-component-C-2\vm\Lib\site-packages\werkzeug\_internal.py L224 
[2023-09-04 20:19:52,496] INFO _log() L224  127.0.0.1 - - [04/Sep/2023 20:19:52] "[36mGET /openapi/static/js/swagger-ui-bundle.js HTTP/1.1[0m" 304 - - call_trace=C:\mvp\puc-rio-mvp-sprint-3-component-C-2\vm\Lib\site-packages\werkzeug\_internal.py L224 
[2023-09-04 20:19:52,496] INFO _log() L224  127.0.0.1 - - [04/Sep/2023 20:19:52] "[36mGET /openapi/static/js/swagger-ui-standalone-preset.js HTTP/1.1[0m" 304 - - call_trace=C:\mvp\puc-rio-mvp-sprint-3-component-C-2\vm\Lib\site-packages\werkzeug\_internal.py L224 
[2023-09-04 20:19:52,610] INFO _log() L224  127.0.0.1 - - [04/Sep/2023 20:19:52] "GET /openapi/openapi.json HTTP/1.1" 200 - - call_trace=C:\mvp\puc-rio-mvp-sprint-3-component-C-2\vm\Lib\site-packages\werkzeug\_internal.py L224 
[2023-09-04 20:19:52,616] INFO _log() L224  127.0.0.1 - - [04/Sep/2023 20:19:52] "[36mGET /openapi/static/images/swagger.svg HTTP/1.1[0m" 304 - - call_trace=C:\mvp\puc-rio-mvp-sprint-3-component-C-2\vm\Lib\site-packages\werkzeug\_internal.py L224 
[2023-09-04 20:20:01,653] ERROR log_exception() L1449 Exception on /marca [POST] - call_trace=C:\mvp\puc-rio-mvp-sprint-3-component-C-2\vm\Lib\site-packages\flask\app.py L1449
Traceback (most recent call last):
  File "C:\mvp\puc-rio-mvp-sprint-3-component-C-2\vm\Lib\site-packages\flask\app.py", line 2073, in wsgi_app
    response = self.full_dispatch_request()
               ^^^^^^^^^^^^^^^^^^^^^^^^^^^^
  File "C:\mvp\puc-rio-mvp-sprint-3-component-C-2\vm\Lib\site-packages\flask\app.py", line 1519, in full_dispatch_request
    rv = self.handle_user_exception(e)
         ^^^^^^^^^^^^^^^^^^^^^^^^^^^^^
  File "C:\mvp\puc-rio-mvp-sprint-3-component-C-2\vm\Lib\site-packages\flask_cors\extension.py", line 165, in wrapped_function
    return cors_after_request(app.make_response(f(*args, **kwargs)))
                                                ^^^^^^^^^^^^^^^^^^
  File "C:\mvp\puc-rio-mvp-sprint-3-component-C-2\vm\Lib\site-packages\flask\app.py", line 1517, in full_dispatch_request
    rv = self.dispatch_request()
         ^^^^^^^^^^^^^^^^^^^^^^^
  File "C:\mvp\puc-rio-mvp-sprint-3-component-C-2\vm\Lib\site-packages\flask\app.py", line 1503, in dispatch_request
    return self.ensure_sync(self.view_functions[rule.endpoint])(**req.view_args)
           ^^^^^^^^^^^^^^^^^^^^^^^^^^^^^^^^^^^^^^^^^^^^^^^^^^^^^^^^^^^^^^^^^^^^^
  File "C:\mvp\puc-rio-mvp-sprint-3-component-C-2\vm\Lib\site-packages\flask_openapi3\scaffold.py", line 191, in wrapper
    resp = _do_wrapper(
           ^^^^^^^^^^^^
  File "C:\mvp\puc-rio-mvp-sprint-3-component-C-2\vm\Lib\site-packages\flask_openapi3\do_wrapper.py", line 135, in _do_wrapper
    response = func(**request_kwargs)
               ^^^^^^^^^^^^^^^^^^^^^^
  File "C:\mvp\puc-rio-mvp-sprint-3-component-C-2\app.py", line 53, in add_marca
    marca = Marca(
      ^^^^^^^^^^^^
  File "<string>", line 4, in __init__
  File "C:\mvp\puc-rio-mvp-sprint-3-component-C-2\vm\Lib\site-packages\sqlalchemy\orm\state.py", line 476, in _initialize_instance
    manager.dispatch.init(self, args, kwargs)
  File "C:\mvp\puc-rio-mvp-sprint-3-component-C-2\vm\Lib\site-packages\sqlalchemy\event\attr.py", line 334, in __call__
    fn(*args, **kw)
  File "C:\mvp\puc-rio-mvp-sprint-3-component-C-2\vm\Lib\site-packages\sqlalchemy\orm\mapper.py", line 3672, in _event_on_init
    instrumenting_mapper._check_configure()
  File "C:\mvp\puc-rio-mvp-sprint-3-component-C-2\vm\Lib\site-packages\sqlalchemy\orm\mapper.py", line 1924, in _check_configure
    _configure_registries({self.registry}, cascade=True)
  File "C:\mvp\puc-rio-mvp-sprint-3-component-C-2\vm\Lib\site-packages\sqlalchemy\orm\mapper.py", line 3483, in _configure_registries
    _do_configure_registries(registries, cascade)
  File "C:\mvp\puc-rio-mvp-sprint-3-component-C-2\vm\Lib\site-packages\sqlalchemy\orm\mapper.py", line 3522, in _do_configure_registries
    mapper._post_configure_properties()
  File "C:\mvp\puc-rio-mvp-sprint-3-component-C-2\vm\Lib\site-packages\sqlalchemy\orm\mapper.py", line 1941, in _post_configure_properties
    prop.init()
  File "C:\mvp\puc-rio-mvp-sprint-3-component-C-2\vm\Lib\site-packages\sqlalchemy\orm\interfaces.py", line 231, in init
    self.do_init()
  File "C:\mvp\puc-rio-mvp-sprint-3-component-C-2\vm\Lib\site-packages\sqlalchemy\orm\relationships.py", line 2150, in do_init
    self._generate_backref()
  File "C:\mvp\puc-rio-mvp-sprint-3-component-C-2\vm\Lib\site-packages\sqlalchemy\orm\relationships.py", line 2486, in _generate_backref
    self._add_reverse_property(self.back_populates)
  File "C:\mvp\puc-rio-mvp-sprint-3-component-C-2\vm\Lib\site-packages\sqlalchemy\orm\relationships.py", line 2078, in _add_reverse_property
    raise sa_exc.ArgumentError(
sqlalchemy.exc.ArgumentError: reverse_property 'modelo' on relationship Modelo.veiculos references relationship Veiculo.modelo, which does not reference mapper mapped class Modelo->modelo
[2023-09-04 20:20:01,661] INFO _log() L224  127.0.0.1 - - [04/Sep/2023 20:20:01] "[35m[1mPOST /marca HTTP/1.1[0m" 500 - - call_trace=C:\mvp\puc-rio-mvp-sprint-3-component-C-2\vm\Lib\site-packages\werkzeug\_internal.py L224 
[2023-09-04 20:20:56,295] INFO _log() L224   * Running on all addresses (0.0.0.0)
   WARNING: This is a development server. Do not use it in a production deployment.
 * Running on http://127.0.0.1:5000
 * Running on http://192.168.15.138:5000 (Press CTRL+C to quit) - call_trace=C:\mvp\puc-rio-mvp-sprint-3-component-C-2\vm\Lib\site-packages\werkzeug\_internal.py L224 
[2023-09-04 20:21:02,241] INFO _log() L224  127.0.0.1 - - [04/Sep/2023 20:21:02] "GET /openapi/swagger HTTP/1.1" 200 - - call_trace=C:\mvp\puc-rio-mvp-sprint-3-component-C-2\vm\Lib\site-packages\werkzeug\_internal.py L224 
[2023-09-04 20:21:02,336] INFO _log() L224  127.0.0.1 - - [04/Sep/2023 20:21:02] "[36mGET /openapi/static/css/swagger-ui.css HTTP/1.1[0m" 304 - - call_trace=C:\mvp\puc-rio-mvp-sprint-3-component-C-2\vm\Lib\site-packages\werkzeug\_internal.py L224 
[2023-09-04 20:21:02,342] INFO _log() L224  127.0.0.1 - - [04/Sep/2023 20:21:02] "[36mGET /openapi/static/js/swagger-ui-bundle.js HTTP/1.1[0m" 304 - - call_trace=C:\mvp\puc-rio-mvp-sprint-3-component-C-2\vm\Lib\site-packages\werkzeug\_internal.py L224 
[2023-09-04 20:21:02,343] INFO _log() L224  127.0.0.1 - - [04/Sep/2023 20:21:02] "[36mGET /openapi/static/js/swagger-ui-standalone-preset.js HTTP/1.1[0m" 304 - - call_trace=C:\mvp\puc-rio-mvp-sprint-3-component-C-2\vm\Lib\site-packages\werkzeug\_internal.py L224 
[2023-09-04 20:21:02,470] INFO _log() L224  127.0.0.1 - - [04/Sep/2023 20:21:02] "GET /openapi/openapi.json HTTP/1.1" 200 - - call_trace=C:\mvp\puc-rio-mvp-sprint-3-component-C-2\vm\Lib\site-packages\werkzeug\_internal.py L224 
